[2022-04-30 12:23:21,783] {taskinstance.py:1043} INFO - Dependencies all met for <TaskInstance: btc_spot_data_dag.results manual__2022-04-30T12:23:05.907695+00:00 [queued]>
[2022-04-30 12:23:21,799] {taskinstance.py:1043} INFO - Dependencies all met for <TaskInstance: btc_spot_data_dag.results manual__2022-04-30T12:23:05.907695+00:00 [queued]>
[2022-04-30 12:23:21,799] {taskinstance.py:1249} INFO - 
--------------------------------------------------------------------------------
[2022-04-30 12:23:21,800] {taskinstance.py:1250} INFO - Starting attempt 1 of 1
[2022-04-30 12:23:21,800] {taskinstance.py:1251} INFO - 
--------------------------------------------------------------------------------
[2022-04-30 12:23:21,874] {taskinstance.py:1270} INFO - Executing <Task(PythonOperator): results> on 2022-04-30 12:23:05.907695+00:00
[2022-04-30 12:23:21,880] {standard_task_runner.py:52} INFO - Started process 5384 to run task
[2022-04-30 12:23:21,886] {standard_task_runner.py:79} INFO - Running: ['***', 'tasks', 'run', 'btc_spot_data_dag', 'results', 'manual__2022-04-30T12:23:05.907695+00:00', '--job-id', '143', '--raw', '--subdir', 'DAGS_FOLDER/my_dag.py', '--cfg-path', '/tmp/tmpw4b_8rt2', '--error-file', '/tmp/tmpp0wvw90u']
[2022-04-30 12:23:21,888] {standard_task_runner.py:80} INFO - Job 143: Subtask results
[2022-04-30 12:23:21,982] {logging_mixin.py:109} INFO - Running <TaskInstance: btc_spot_data_dag.results manual__2022-04-30T12:23:05.907695+00:00 [running]> on host cf4e030da5d2
[2022-04-30 12:23:22,066] {taskinstance.py:1448} INFO - Exporting the following env vars:
AIRFLOW_CTX_DAG_OWNER=***
AIRFLOW_CTX_DAG_ID=btc_spot_data_dag
AIRFLOW_CTX_TASK_ID=results
AIRFLOW_CTX_EXECUTION_DATE=2022-04-30T12:23:05.907695+00:00
AIRFLOW_CTX_DAG_RUN_ID=manual__2022-04-30T12:23:05.907695+00:00
[2022-04-30 12:23:24,133] {logging_mixin.py:109} INFO - 2105.364909510002
[2022-04-30 12:23:24,443] {taskinstance.py:1774} ERROR - Task failed with exception
Traceback (most recent call last):
  File "/home/airflow/.local/lib/python3.7/site-packages/airflow/operators/python.py", line 174, in execute
    return_value = self.execute_callable()
  File "/home/airflow/.local/lib/python3.7/site-packages/airflow/operators/python.py", line 188, in execute_callable
    return self.python_callable(*self.op_args, **self.op_kwargs)
  File "/opt/airflow/dags/results.py", line 27, in _calculate_results
    print(row[1])
  File "/home/airflow/.local/lib/python3.7/site-packages/google/cloud/bigquery/table.py", line 1411, in __getitem__
    return self._xxx_values[key]
IndexError: tuple index out of range
[2022-04-30 12:23:24,467] {taskinstance.py:1288} INFO - Marking task as FAILED. dag_id=btc_spot_data_dag, task_id=results, execution_date=20220430T122305, start_date=20220430T122321, end_date=20220430T122324
[2022-04-30 12:23:24,487] {standard_task_runner.py:98} ERROR - Failed to execute job 143 for task results (tuple index out of range; 5384)
[2022-04-30 12:23:24,507] {local_task_job.py:154} INFO - Task exited with return code 1
[2022-04-30 12:23:24,550] {local_task_job.py:264} INFO - 0 downstream tasks scheduled from follow-on schedule check
